Workbook

Sheet Rules
A1: Label audit: rules (defined before reviewing)
A3: Error type
A4: False positive | B4: Appears in *_pred.jpg but NOT in *_labels.jpg
A5: False negative | B5: Appears in *_labels.jpg but the model did NOT detect it in *_pred.jpg
A7: Verdict (false positives)
A8: Missing label | B8: Clear, complete, visible leaf or stem that should have been labeled
A9: Unclear | B9: More than half outside the frame, heavily occluded, or not distinguishable at this resolution
A10: Model error | B10: Duplicate mask on the same object, or something that is not a leaf or stem (ear of corn, hand, soil, text)
A12: Likely cause (false negatives)
A13: Thin / Small | B13: Narrow or distant object (typical of stems)
A14: Occluded | B14: Partially covered by another leaf
A15: Border | B15: Cut by the image frame
A16: Unknown | B16: No apparent reason
A18: Sample and method
A19: Sample | B19: All 16 images of val_batch0 (yolo11n-seg, first validation batch), reviewed in order
A20: Rows | B20: One row per error, not per image
A21: Image ID | B21: R = row and I = image position in the 4x4 val_batch0 mosaic
A22: Caveat | B22: Reviewed from downsized mosaic images; 'Unclear' cases and the counts for R2/I3 are approximate

Sheet Audit
A1: Image | B1: Error type | C1: Class | D1: Confidence | E1: Verdict | F1: Likely cause (FN) | G1: Note
A2: val_batch0 / R1 / I1 | B2: False positive | C2: Leaf | D2: 0.7 | E2: Missing label | G2: Clear leaf, left-center
A3: val_batch0 / R1 / I1 | B3: False positive | C3: Leaf | D3: 0.7 | E3: Missing label | G3: Large leaf, bottom right
A4: val_batch0 / R1 / I1 | B4: False positive | C4: Leaf | E4: Unclear | G4: Top-right corner, cut by the border; confidence unreadable
A5: val_batch0 / R1 / I2 | B5: False positive | C5: Leaf | D5: 0.3 | E5: Model error | G5: Duplicate: second box on the diagonal leaf in the center
A6: val_batch0 / R1 / I2 | B6: False positive | C6: Leaf | D6: 0.9 | E6: Unclear | G6: Bottom center, label hidden; may duplicate the 0.4 prediction
A7: val_batch0 / R1 / I4 | B7: False positive | C7: Leaf | D7: 0.8 | E7: Model error | G7: Ear of corn (husk), not a leaf
A8: val_batch0 / R1 / I4 | B8: False positive | C8: Leaf | D8: 0.4 | E8: Model error | G8: Duplicate: large box on the same ear of corn
A9: val_batch0 / R1 / I4 | B9: False positive | C9: Stem | D9: 0.4 | E9: Unclear | G9: Bottom center; possibly the continuation of the labeled stem
A10: val_batch0 / R1 / I4 | B10: False positive | C10: Leaf | D10: 0.4 | E10: Unclear | G10: Bottom right, next to the person's arm
A11: val_batch0 / R2 / I1 | B11: False positive | C11: Leaf | D11: 0.7 | E11: Missing label | G11: Visible leaf on the left
A12: val_batch0 / R2 / I1 | B12: False positive | C12: Leaf | D12: 0.3 | E12: Unclear | G12: Top left, low confidence
A13: val_batch0 / R2 / I1 | B13: False positive | C13: Stem | D13: 0.3 | E13: Model error | G13: Wrong class: stem predicted on the small leaf in the center
A14: val_batch0 / R2 / I2 | B14: False positive | C14: Leaf | D14: 0.7 | E14: Model error | G14: Duplicate of the large diagonal leaf (1)
A15: val_batch0 / R2 / I2 | B15: False positive | C15: Leaf | D15: 0.7 | E15: Model error | G15: Duplicate of the large diagonal leaf (2)
A16: val_batch0 / R2 / I2 | B16: False positive | C16: Stem | D16: 0.7 | E16: Model error | G16: Duplicate of the upper central stem
... A24: val_batch0 / R3 / I1 | B24: False positive | C24: Leaf | D24: 0.3 | E24: Model error | G24: Thin object next to the scissors; not a leaf
A25: val_batch0 / R3 / I1 | B25: False positive | C25: Leaf | E25: Model error | G25: Wrong class: the central stem predicted as a leaf
A26: val_batch0 / R3 / I1 | B26: False positive | C26: Leaf | D26: 0.4 | E26: Model error | G26: Duplicate over the central stem area
A27: val_batch0 / R3 / I3 | B27: False positive | C27: Leaf | D27: 0.4 | E27: Model error | G27: Duplicate on the horizontal leaf at the top (1)
A28: val_batch0 / R3 / I3 | B28: False positive | C28: Leaf | D28: 0.8 | E28: Model error | G28: Duplicate on the horizontal leaf at the top (2)
A29: val_batch0 / R3 / I3 | B29: False positive | C29: Stem | D29: 0.6 | E29: Unclear | G29: Top center, possible stem between leaves
A30: val_batch0 / R4 / I1 | B30: False positive | C30: Leaf | D30: 0.4 | E30: Unclear | G30: Top center, piece of a leaf
A31: val_batch0 / R4 / I1 | B31: False positive | C31: Leaf | E31: Missing label | G31: Top-right border, visible vertical leaf; confidence unreadable
A32: val_batch0 / R4 / I1 | B32: False positive | C32: Stem | D32: 0.4 | E32: Unclear | G32: Bottom center; possibly the continuation of the stem
A33: val_batch0 / R4 / I2 | B33: False positive | C33: Leaf | D33: 0.3 | E33: Unclear | G33: Bottom right, seedling on the ground
A34: val_batch0 / R4 / I3 | B34: False positive | C34: Leaf | E34: Model error | G34: Duplicate on the horizontal leaf at the top (1)
A35: val_batch0 / R4 / I3 | B35: False positive | C35: Leaf | E35: Model error | G35: Duplicate on the horizontal leaf at the top (2)
A36: val_batch0 / R4 / I3 | B36: False positive | C36: Stem | D36: 0.6 | E36: Unclear | G36: Top right, visible unlabeled stem
A37: val_batch0 / R4 / I4 | B37: False positive | C37: Leaf | D37: 0.3 | E37: Missing label | G37: Horizontal leaf on the left, mid-ground
A38: val_batch0 / R4 / I4 | B38: False positive | C38: Leaf | D38: 0.6 | E38: Missing label | G38: Leaf in the center, mid-ground
A39: val_batch0 / R4 / I4 | B39: False positive | C39: Leaf | D39: 0.3 | E39: Unclear | G39: Bottom left, small leaf near the ground
A40: val_batch0 / R1 / I2 | B40: False negative | C40: Leaf | E40: False negative | F40: Thin | G40: Tall narrow leaf on the right, backlit
A41: val_batch0 / R1 / I2 | B41: False negative | C41: Stem | E41: False negative | F41: Thin | G41: Thin stem on the right
A42: val_batch0 / R1 / I3 | B42: False negative | C42: Leaf | E42: False negative | F42: Occluded | G42: Top-center leaf
A43: val_batch0 / R1 / I3 | B43: False negative | C43: Leaf | E43: False negative | F43: Occluded | G43: Central leaf
A44: val_batch0 / R1 / I3 | B44: False negative | C44: Leaf | E44: False negative | F44: Occluded | G44: Lower-left leaf
A45: val_batch0 / R1 / I3 | B45: False negative | C45: Stem | E45: False negative | F45: Small | G45: Small stem, bottom center (1)
A46: val_batch0 / R1 / I3 | B46: False negative | C46: Stem | E46: False negative | F46: Small | G46: Small stem, bottom center (2)
A47: val_batch0 / R1 / I4 | B47: False negative | C47: Stem | E47: False negative | F47: Thin | G47: Second stem, right of the main one
...

Sheet Summary
A1: Label audit summary
A3: Images reviewed | B3: 16
A5: False positives by verdict | B5: Total | C5: Leaf | D5: Stem | E5: Share
A6: Missing label | B6: =COUNTIFS(Audit!$B$2:$B$98,"False positive",Audit!$E$2:$E$98,"Missing label") -> 8 | C6: =COUNTIFS(Audit!$B$2:$B$98,"False positive",Audit!$E$2:$E$98,"Missing label",Audit!$C$2:$C$98,"Leaf") -> 8 | D6: =COUNTIFS(Audit!$B$2:$B$98,"False positive",Audit!$E$2:$E$98,"Missing label",Audit!$C$2:$C$98,"Stem") -> 0 | E6: =IF($B$9=0,0,B6/$B$9) -> 0.21052632
A7: Model error | B7: =COUNTIFS(Audit!$B$2:$B$98,"False positive",Audit!$E$2:$E$98,"Model error") -> 14 | C7: =COUNTIFS(Audit!$B$2:$B$98,"False positive",Audit!$E$2:$E$98,"Model error",Audit!$C$2:$C$98,"Leaf") -> 12 | D7: =COUNTIFS(Audit!$B$2:$B$98,"False positive",Audit!$E$2:$E$98,"Model error",Audit!$C$2:$C$98,"Stem") -> 2 | E7: =IF($B$9=0,0,B7/$B$9) -> 0.36842105
A8: Unclear | B8: =COUNTIFS(Audit!$B$2:$B$98,"False positive",Audit!$E$2:$E$98,"Unclear") -> 16 | C8: =COUNTIFS(Audit!$B$2:$B$98,"False positive",Audit!$E$2:$E$98,"Unclear",Audit!$C$2:$C$98,"Leaf") -> 11 | D8: =COUNTIFS(Audit!$B$2:$B$98,"False positive",Audit!$E$2:$E$98,"Unclear",Audit!$C$2:$C$98,"Stem") -> 5 | E8: =IF($B$9=0,0,B8/$B$9) -> 0.42105263
A9: Total false positives | B9: =SUM(B6:B8) -> 38 | C9: =SUM(C6:C8) -> 31 | D9: =SUM(D6:D8) -> 7 | E9: =IF(B9=0,0,SUM(E6:E8)) -> 1
A11: False negatives by likely cause | B11: Total | C11: Leaf | D11: Stem
A12: Thin | B12: =COUNTIFS(Audit!$B$2:$B$98,"False negative",Audit!$F$2:$F$98,"Thin") -> 11 | C12: =COUNTIFS(Audit!$B$2:$B$98,"False negative",Audit!$F$2:$F$98,"Thin",Audit!$C$2:$C$98,"Leaf") -> 1 | D12: =COUNTIFS(Audit!$B$2:$B$98,"False negative",Audit!$F$2:$F$98,"Thin",Audit!$C$2:$C$98,"Stem") -> 10
A13: Small | B13: =COUNTIFS(Audit!$B$2:$B$98,"False negative",Audit!$F$2:$F$98,"Small") -> 6 | C13: =COUNTIFS(Audit!$B$2:$B$98,"False negative",Audit!$F$2:$F$98,"Small",Audit!$C$2:$C$98,"Leaf") -> 0 | D13: =COUNTIFS(Audit!$B$2:$B$98,"False negative",Audit!$F$2:$F$98,"Small",Audit!$C$2:$C$98,"Stem") -> 6
A14: Occluded | B14: =COUNTIFS(Audit!$B$2:$B$98,"False negative",Audit!$F$2:$F$98,"Occluded") -> 9 | C14: =COUNTIFS(Audit!$B$2:$B$98,"False negative",Audit!$F$2:$F$98,"Occluded",Audit!$C$2:$C$98,"Leaf") -> 4 | D14: =COUNTIFS(Audit!$B$2:$B$98,"False negative",Audit!$F$2:$F$98,"Occluded",Audit!$C$2:$C$98,"Stem") -> 5
A15: Border | B15: =COUNTIFS(Audit!$B$2:$B$98,"False negative",Audit!$F$2:$F$98,"Border") -> 1 | C15: =COUNTIFS(Audit!$B$2:$B$98,"False negative",Audit!$F$2:$F$98,"Border",Audit!$C$2:$C$98,"Leaf") -> 0 | D15: =COUNTIFS(Audit!$B$2:$B$98,"False negative",Audit!$F$2:$F$98,"Border",Audit!$C$2:$C$98,"Stem") -> 1
A16: Blurry | B16: =COUNTIFS(Audit!$B$2:$B$98,"False negative",Audit!$F$2:$F$98,"Blurry") -> 0 | C16: =COUNTIFS(Audit!$B$2:$B$98,"False negative",Audit!$F$2:$F$98,"Blurry",Audit!$C$2:$C$98,"Leaf") -> 0 | D16: =COUNTIFS(Audit!$B$2:$B$98,"False negative",Audit!$F$2:$F$98,"Blurry",Audit!$C$2:$C$98,"Stem") -> 0
A17: Unknown | B17: =COUNTIFS(Audit!$B$2:$B$98,"False negative",Audit!$F$2:$F$98,"Unknown") -> 1 | C17: =COUNTIFS(Audit!$B$2:$B$98,"False negative",Audit!$F$2:$F$98,"Unknown",Audit!$C$2:$C$98,"Leaf") -> 0 | D17: =COUNTIFS(Audit!$B$2:$B$98,"False negative",Audit!$F$2:$F$98,"Unknown",Audit!$C$2:$C$98,"Stem") -> 1
A18: Total false negatives | B18: =SUM(B12:B17) -> 28 | C18: =SUM(C12:C17) -> 5 | D18: =SUM(D12:D17) -> 23
A20: Summary sentence
A21: ="In a sample of "&B3&" validation images, "&TEXT(E6,"0%")&" of the "&B9&" false positives were visible objects missing from the labels, "&TEXT(E7,"0%")&" were model errors and "&TEXT(E8,"0%")&" were unclear. The model missed "&B18&" labeled objects ("&D18&" stems)." -> In a sample of 16 validation images, 21% of the 38 false positives were visible objects missing from the labels, 37% were model errors and 42% were unclear. The model missed 28 labeled objects (23 stems).
